<mujoco model="production line instances">
  <worldbody>
<body name="jar_02_bamboo_leaf_bottom" pos="-0.58 0.5600 0.4884" euler="0 0 0">
    <freejoint name="jar_02_bamboo_leaf_bottom_freejoint"/>
    <body name="jar_02_bamboo_leaf_bottom_seg_05">
    <geom name="jar_02_bamboo_leaf_bottom_seg_05_geom" type="box" size="0.02138 0.05500 0.00150" material="compliant_bamboo_mat_bottom" mass="0.000909" friction="4 2 1" condim="6" contype="1" conaffinity="5"/>
    <site name="jar_02_bamboo_leaf_bottom_pick_site" pos="0 0 0.00450" type="sphere" size="0.007" rgba="0 1 0 0.7"/>
    <site name="jar_02_bamboo_leaf_bottom_center_site" pos="0 0 0.00350" type="sphere" size="0.006" rgba="1 0 0 0.6"/>
      <body name="jar_02_bamboo_leaf_bottom_seg_06" pos="0.03818 0 0">
      <joint name="jar_02_bamboo_leaf_bottom_bend_06" type="hinge" axis="0 1 0" pos="-0.01909 0 0" range="-1.57 1.57" damping="0.012" stiffness="0.045" armature="0.0002" limited="true"/>
      <geom name="jar_02_bamboo_leaf_bottom_seg_06_geom" type="box" size="0.02138 0.04580 0.00150" material="compliant_bamboo_mat_bottom" mass="0.000909" friction="4 2 1" condim="6" contype="1" conaffinity="5"/>
      <body name="jar_02_bamboo_leaf_bottom_seg_07" pos="0.03818 0 0">
      <joint name="jar_02_bamboo_leaf_bottom_bend_07" type="hinge" axis="0 1 0" pos="-0.01909 0 0" range="-1.57 1.57" damping="0.012" stiffness="0.045" armature="0.0002" limited="true"/>
      <geom name="jar_02_bamboo_leaf_bottom_seg_07_geom" type="box" size="0.02138 0.04130 0.00150" material="compliant_bamboo_mat_bottom" mass="0.000909" friction="4 2 1" condim="6" contype="1" conaffinity="5"/>
      <body name="jar_02_bamboo_leaf_bottom_seg_08" pos="0.03818 0 0">
      <joint name="jar_02_bamboo_leaf_bottom_bend_08" type="hinge" axis="0 1 0" pos="-0.01909 0 0" range="-1.57 1.57" damping="0.012" stiffness="0.045" armature="0.0002" limited="true"/>
      <geom name="jar_02_bamboo_leaf_bottom_seg_08_geom" type="box" size="0.02138 0.03670 0.00150" material="compliant_bamboo_mat_bottom" mass="0.000909" friction="4 2 1" condim="6" contype="1" conaffinity="5"/>
      <body name="jar_02_bamboo_leaf_bottom_seg_09" pos="0.03818 0 0">
      <joint name="jar_02_bamboo_leaf_bottom_bend_09" type="hinge" axis="0 1 0" pos="-0.01909 0 0" range="-1.57 1.57" damping="0.012" stiffness="0.045" armature="0.0002" limited="true"/>
      <geom name="jar_02_bamboo_leaf_bottom_seg_09_geom" type="box" size="0.02138 0.02640 0.00150" material="compliant_bamboo_mat_bottom" mass="0.000909" friction="4 2 1" condim="6" contype="1" conaffinity="5"/>
      <body name="jar_02_bamboo_leaf_bottom_seg_10" pos="0.03818 0 0">
      <joint name="jar_02_bamboo_leaf_bottom_bend_10" type="hinge" axis="0 1 0" pos="-0.01909 0 0" range="-1.57 1.57" damping="0.012" stiffness="0.045" armature="0.0002" limited="true"/>
      <geom name="jar_02_bamboo_leaf_bottom_seg_10_geom" type="box" size="0.02138 0.01320 0.00150" material="compliant_bamboo_mat_bottom" mass="0.000909" friction="4 2 1" condim="6" contype="1" conaffinity="5"/>
      </body>
      </body>
      </body>
      </body>
      </body>
      <body name="jar_02_bamboo_leaf_bottom_seg_04" pos="-0.03818 0 0">
      <joint name="jar_02_bamboo_leaf_bottom_bend_05" type="hinge" axis="0 -1 0" pos="0.01909 0 0" range="-1.57 1.57" damping="0.012" stiffness="0.045" armature="0.0002" limited="true"/>
      <geom name="jar_02_bamboo_leaf_bottom_seg_04_geom" type="box" size="0.02138 0.04580 0.00150" material="compliant_bamboo_mat_bottom" mass="0.000909" friction="4 2 1" condim="6" contype="1" conaffinity="5"/>
      <body name="jar_02_bamboo_leaf_bottom_seg_03" pos="-0.03818 0 0">
      <joint name="jar_02_bamboo_leaf_bottom_bend_04" type="hinge" axis="0 -1 0" pos="0.01909 0 0" range="-1.57 1.57" damping="0.012" stiffness="0.045" armature="0.0002" limited="true"/>
      <geom name="jar_02_bamboo_leaf_bottom_seg_03_geom" type="box" size="0.02138 0.04130 0.00150" material="compliant_bamboo_mat_bottom" mass="0.000909" friction="4 2 1" condim="6" contype="1" conaffinity="5"/>
      <body name="jar_02_bamboo_leaf_bottom_seg_02" pos="-0.03818 0 0">
      <joint name="jar_02_bamboo_leaf_bottom_bend_03" type="hinge" axis="0 -1 0" pos="0.01909 0 0" range="-1.57 1.57" damping="0.012" stiffness="0.045" armature="0.0002" limited="true"/>
      <geom name="jar_02_bamboo_leaf_bottom_seg_02_geom" type="box" size="0.02138 0.03670 0.00150" material="compliant_bamboo_mat_bottom" mass="0.000909" friction="4 2 1" condim="6" contype="1" conaffinity="5"/>
      <body name="jar_02_bamboo_leaf_bottom_seg_01" pos="-0.03818 0 0">
      <joint name="jar_02_bamboo_leaf_bottom_bend_02" type="hinge" axis="0 -1 0" pos="0.01909 0 0" range="-1.57 1.57" damping="0.012" stiffness="0.045" armature="0.0002" limited="true"/>
      <geom name="jar_02_bamboo_leaf_bottom_seg_01_geom" type="box" size="0.02138 0.02640 0.00150" material="compliant_bamboo_mat_bottom" mass="0.000909" friction="4 2 1" condim="6" contype="1" conaffinity="5"/>
      <body name="jar_02_bamboo_leaf_bottom_seg_00" pos="-0.03818 0 0">
      <joint name="jar_02_bamboo_leaf_bottom_bend_01" type="hinge" axis="0 -1 0" pos="0.01909 0 0" range="-1.57 1.57" damping="0.012" stiffness="0.045" armature="0.0002" limited="true"/>
      <geom name="jar_02_bamboo_leaf_bottom_seg_00_geom" type="box" size="0.02138 0.01320 0.00150" material="compliant_bamboo_mat_bottom" mass="0.000909" friction="4 2 1" condim="6" contype="1" conaffinity="5"/>
      </body>
      </body>
      </body>
      </body>
      </body>
    </body>
    </body>
    <body name="jar_02_bamboo_leaf_top" pos="-0.58 0.5600 0.4918" euler="0 0 0">
    <freejoint name="jar_02_bamboo_leaf_top_freejoint"/>
    <body name="jar_02_bamboo_leaf_top_seg_05">
    <geom name="jar_02_bamboo_leaf_top_seg_05_geom" type="box" size="0.02138 0.05500 0.00150" material="compliant_bamboo_mat_top" mass="0.000909" friction="4 2 1" condim="6" contype="1" conaffinity="5"/>
    <site name="jar_02_bamboo_leaf_top_pick_site" pos="0 0 0.00450" type="sphere" size="0.007" rgba="0 1 0 0.7"/>
    <site name="jar_02_bamboo_leaf_top_center_site" pos="0 0 0.00350" type="sphere" size="0.006" rgba="1 0 0 0.6"/>
      <body name="jar_02_bamboo_leaf_top_seg_06" pos="0.03818 0 0">
      <joint name="jar_02_bamboo_leaf_top_bend_06" type="hinge" axis="0 1 0" pos="-0.01909 0 0" range="-1.57 1.57" damping="0.012" stiffness="0.045" armature="0.0002" limited="true"/>
      <geom name="jar_02_bamboo_leaf_top_seg_06_geom" type="box" size="0.02138 0.04580 0.00150" material="compliant_bamboo_mat_top" mass="0.000909" friction="4 2 1" condim="6" contype="1" conaffinity="5"/>
      <body name="jar_02_bamboo_leaf_top_seg_07" pos="0.03818 0 0">
      <joint name="jar_02_bamboo_leaf_top_bend_07" type="hinge" axis="0 1 0" pos="-0.01909 0 0" range="-1.57 1.57" damping="0.012" stiffness="0.045" armature="0.0002" limited="true"/>
      <geom name="jar_02_bamboo_leaf_top_seg_07_geom" type="box" size="0.02138 0.04130 0.00150" material="compliant_bamboo_mat_top" mass="0.000909" friction="4 2 1" condim="6" contype="1" conaffinity="5"/>
      <body name="jar_02_bamboo_leaf_top_seg_08" pos="0.03818 0 0">
      <joint name="jar_02_bamboo_leaf_top_bend_08" type="hinge" axis="0 1 0" pos="-0.01909 0 0" range="-1.57 1.57" damping="0.012" stiffness="0.045" armature="0.0002" limited="true"/>
      <geom name="jar_02_bamboo_leaf_top_seg_08_geom" type="box" size="0.02138 0.03670 0.00150" material="compliant_bamboo_mat_top" mass="0.000909" friction="4 2 1" condim="6" contype="1" conaffinity="5"/>
      <body name="jar_02_bamboo_leaf_top_seg_09" pos="0.03818 0 0">
      <joint name="jar_02_bamboo_leaf_top_bend_09" type="hinge" axis="0 1 0" pos="-0.01909 0 0" range="-1.57 1.57" damping="0.012" stiffness="0.045" armature="0.0002" limited="true"/>
      <geom name="jar_02_bamboo_leaf_top_seg_09_geom" type="box" size="0.02138 0.02640 0.00150" material="compliant_bamboo_mat_top" mass="0.000909" friction="4 2 1" condim="6" contype="1" conaffinity="5"/>
      <body name="jar_02_bamboo_leaf_top_seg_10" pos="0.03818 0 0">
      <joint name="jar_02_bamboo_leaf_top_bend_10" type="hinge" axis="0 1 0" pos="-0.01909 0 0" range="-1.57 1.57" damping="0.012" stiffness="0.045" armature="0.0002" limited="true"/>
      <geom name="jar_02_bamboo_leaf_top_seg_10_geom" type="box" size="0.02138 0.01320 0.00150" material="compliant_bamboo_mat_top" mass="0.000909" friction="4 2 1" condim="6" contype="1" conaffinity="5"/>
      </body>
      </body>
      </body>
      </body>
      </body>
      <body name="jar_02_bamboo_leaf_top_seg_04" pos="-0.03818 0 0">
      <joint name="jar_02_bamboo_leaf_top_bend_05" type="hinge" axis="0 -1 0" pos="0.01909 0 0" range="-1.57 1.57" damping="0.012" stiffness="0.045" armature="0.0002" limited="true"/>
      <geom name="jar_02_bamboo_leaf_top_seg_04_geom" type="box" size="0.02138 0.04580 0.00150" material="compliant_bamboo_mat_top" mass="0.000909" friction="4 2 1" condim="6" contype="1" conaffinity="5"/>
      <body name="jar_02_bamboo_leaf_top_seg_03" pos="-0.03818 0 0">
      <joint name="jar_02_bamboo_leaf_top_bend_04" type="hinge" axis="0 -1 0" pos="0.01909 0 0" range="-1.57 1.57" damping="0.012" stiffness="0.045" armature="0.0002" limited="true"/>
      <geom name="jar_02_bamboo_leaf_top_seg_03_geom" type="box" size="0.02138 0.04130 0.00150" material="compliant_bamboo_mat_top" mass="0.000909" friction="4 2 1" condim="6" contype="1" conaffinity="5"/>
      <body name="jar_02_bamboo_leaf_top_seg_02" pos="-0.03818 0 0">
      <joint name="jar_02_bamboo_leaf_top_bend_03" type="hinge" axis="0 -1 0" pos="0.01909 0 0" range="-1.57 1.57" damping="0.012" stiffness="0.045" armature="0.0002" limited="true"/>
      <geom name="jar_02_bamboo_leaf_top_seg_02_geom" type="box" size="0.02138 0.03670 0.00150" material="compliant_bamboo_mat_top" mass="0.000909" friction="4 2 1" condim="6" contype="1" conaffinity="5"/>
      <body name="jar_02_bamboo_leaf_top_seg_01" pos="-0.03818 0 0">
      <joint name="jar_02_bamboo_leaf_top_bend_02" type="hinge" axis="0 -1 0" pos="0.01909 0 0" range="-1.57 1.57" damping="0.012" stiffness="0.045" armature="0.0002" limited="true"/>
      <geom name="jar_02_bamboo_leaf_top_seg_01_geom" type="box" size="0.02138 0.02640 0.00150" material="compliant_bamboo_mat_top" mass="0.000909" friction="4 2 1" condim="6" contype="1" conaffinity="5"/>
      <body name="jar_02_bamboo_leaf_top_seg_00" pos="-0.03818 0 0">
      <joint name="jar_02_bamboo_leaf_top_bend_01" type="hinge" axis="0 -1 0" pos="0.01909 0 0" range="-1.57 1.57" damping="0.012" stiffness="0.045" armature="0.0002" limited="true"/>
      <geom name="jar_02_bamboo_leaf_top_seg_00_geom" type="box" size="0.02138 0.01320 0.00150" material="compliant_bamboo_mat_top" mass="0.000909" friction="4 2 1" condim="6" contype="1" conaffinity="5"/>
      </body>
      </body>
      </body>
      </body>
      </body>
    </body>
    </body>

<body name="jar_03_bamboo_leaf_bottom" pos="-0.58 0.5600 0.4816" euler="0 0 0">
    <freejoint name="jar_03_bamboo_leaf_bottom_freejoint"/>
    <body name="jar_03_bamboo_leaf_bottom_seg_05">
    <geom name="jar_03_bamboo_leaf_bottom_seg_05_geom" type="box" size="0.02138 0.05500 0.00150" material="compliant_bamboo_mat_bottom" mass="0.000909" friction="4 2 1" condim="6" contype="1" conaffinity="5"/>
    <site name="jar_03_bamboo_leaf_bottom_pick_site" pos="0 0 0.00450" type="sphere" size="0.007" rgba="0 1 0 0.7"/>
    <site name="jar_03_bamboo_leaf_bottom_center_site" pos="0 0 0.00350" type="sphere" size="0.006" rgba="1 0 0 0.6"/>
      <body name="jar_03_bamboo_leaf_bottom_seg_06" pos="0.03818 0 0">
      <joint name="jar_03_bamboo_leaf_bottom_bend_06" type="hinge" axis="0 1 0" pos="-0.01909 0 0" range="-1.57 1.57" damping="0.012" stiffness="0.045" armature="0.0002" limited="true"/>
      <geom name="jar_03_bamboo_leaf_bottom_seg_06_geom" type="box" size="0.02138 0.04580 0.00150" material="compliant_bamboo_mat_bottom" mass="0.000909" friction="4 2 1" condim="6" contype="1" conaffinity="5"/>
      <body name="jar_03_bamboo_leaf_bottom_seg_07" pos="0.03818 0 0">
      <joint name="jar_03_bamboo_leaf_bottom_bend_07" type="hinge" axis="0 1 0" pos="-0.01909 0 0" range="-1.57 1.57" damping="0.012" stiffness="0.045" armature="0.0002" limited="true"/>
      <geom name="jar_03_bamboo_leaf_bottom_seg_07_geom" type="box" size="0.02138 0.04130 0.00150" material="compliant_bamboo_mat_bottom" mass="0.000909" friction="4 2 1" condim="6" contype="1" conaffinity="5"/>
      <body name="jar_03_bamboo_leaf_bottom_seg_08" pos="0.03818 0 0">
      <joint name="jar_03_bamboo_leaf_bottom_bend_08" type="hinge" axis="0 1 0" pos="-0.01909 0 0" range="-1.57 1.57" damping="0.012" stiffness="0.045" armature="0.0002" limited="true"/>
      <geom name="jar_03_bamboo_leaf_bottom_seg_08_geom" type="box" size="0.02138 0.03670 0.00150" material="compliant_bamboo_mat_bottom" mass="0.000909" friction="4 2 1" condim="6" contype="1" conaffinity="5"/>
      <body name="jar_03_bamboo_leaf_bottom_seg_09" pos="0.03818 0 0">
      <joint name="jar_03_bamboo_leaf_bottom_bend_09" type="hinge" axis="0 1 0" pos="-0.01909 0 0" range="-1.57 1.57" damping="0.012" stiffness="0.045" armature="0.0002" limited="true"/>
      <geom name="jar_03_bamboo_leaf_bottom_seg_09_geom" type="box" size="0.02138 0.02640 0.00150" material="compliant_bamboo_mat_bottom" mass="0.000909" friction="4 2 1" condim="6" contype="1" conaffinity="5"/>
      <body name="jar_03_bamboo_leaf_bottom_seg_10" pos="0.03818 0 0">
      <joint name="jar_03_bamboo_leaf_bottom_bend_10" type="hinge" axis="0 1 0" pos="-0.01909 0 0" range="-1.57 1.57" damping="0.012" stiffness="0.045" armature="0.0002" limited="true"/>
      <geom name="jar_03_bamboo_leaf_bottom_seg_10_geom" type="box" size="0.02138 0.01320 0.00150" material="compliant_bamboo_mat_bottom" mass="0.000909" friction="4 2 1" condim="6" contype="1" conaffinity="5"/>
      </body>
      </body>
      </body>
      </body>
      </body>
      <body name="jar_03_bamboo_leaf_bottom_seg_04" pos="-0.03818 0 0">
      <joint name="jar_03_bamboo_leaf_bottom_bend_05" type="hinge" axis="0 -1 0" pos="0.01909 0 0" range="-1.57 1.57" damping="0.012" stiffness="0.045" armature="0.0002" limited="true"/>
      <geom name="jar_03_bamboo_leaf_bottom_seg_04_geom" type="box" size="0.02138 0.04580 0.00150" material="compliant_bamboo_mat_bottom" mass="0.000909" friction="4 2 1" condim="6" contype="1" conaffinity="5"/>
      <body name="jar_03_bamboo_leaf_bottom_seg_03" pos="-0.03818 0 0">
      <joint name="jar_03_bamboo_leaf_bottom_bend_04" type="hinge" axis="0 -1 0" pos="0.01909 0 0" range="-1.57 1.57" damping="0.012" stiffness="0.045" armature="0.0002" limited="true"/>
      <geom name="jar_03_bamboo_leaf_bottom_seg_03_geom" type="box" size="0.02138 0.04130 0.00150" material="compliant_bamboo_mat_bottom" mass="0.000909" friction="4 2 1" condim="6" contype="1" conaffinity="5"/>
      <body name="jar_03_bamboo_leaf_bottom_seg_02" pos="-0.03818 0 0">
      <joint name="jar_03_bamboo_leaf_bottom_bend_03" type="hinge" axis="0 -1 0" pos="0.01909 0 0" range="-1.57 1.57" damping="0.012" stiffness="0.045" armature="0.0002" limited="true"/>
      <geom name="jar_03_bamboo_leaf_bottom_seg_02_geom" type="box" size="0.02138 0.03670 0.00150" material="compliant_bamboo_mat_bottom" mass="0.000909" friction="4 2 1" condim="6" contype="1" conaffinity="5"/>
      <body name="jar_03_bamboo_leaf_bottom_seg_01" pos="-0.03818 0 0">
      <joint name="jar_03_bamboo_leaf_bottom_bend_02" type="hinge" axis="0 -1 0" pos="0.01909 0 0" range="-1.57 1.57" damping="0.012" stiffness="0.045" armature="0.0002" limited="true"/>
      <geom name="jar_03_bamboo_leaf_bottom_seg_01_geom" type="box" size="0.02138 0.02640 0.00150" material="compliant_bamboo_mat_bottom" mass="0.000909" friction="4 2 1" condim="6" contype="1" conaffinity="5"/>
      <body name="jar_03_bamboo_leaf_bottom_seg_00" pos="-0.03818 0 0">
      <joint name="jar_03_bamboo_leaf_bottom_bend_01" type="hinge" axis="0 -1 0" pos="0.01909 0 0" range="-1.57 1.57" damping="0.012" stiffness="0.045" armature="0.0002" limited="true"/>
      <geom name="jar_03_bamboo_leaf_bottom_seg_00_geom" type="box" size="0.02138 0.01320 0.00150" material="compliant_bamboo_mat_bottom" mass="0.000909" friction="4 2 1" condim="6" contype="1" conaffinity="5"/>
      </body>
      </body>
      </body>
      </body>
      </body>
    </body>
    </body>
    <body name="jar_03_bamboo_leaf_top" pos="-0.58 0.5600 0.4850" euler="0 0 0">
    <freejoint name="jar_03_bamboo_leaf_top_freejoint"/>
    <body name="jar_03_bamboo_leaf_top_seg_05">
    <geom name="jar_03_bamboo_leaf_top_seg_05_geom" type="box" size="0.02138 0.05500 0.00150" material="compliant_bamboo_mat_top" mass="0.000909" friction="4 2 1" condim="6" contype="1" conaffinity="5"/>
    <site name="jar_03_bamboo_leaf_top_pick_site" pos="0 0 0.00450" type="sphere" size="0.007" rgba="0 1 0 0.7"/>
    <site name="jar_03_bamboo_leaf_top_center_site" pos="0 0 0.00350" type="sphere" size="0.006" rgba="1 0 0 0.6"/>
      <body name="jar_03_bamboo_leaf_top_seg_06" pos="0.03818 0 0">
      <joint name="jar_03_bamboo_leaf_top_bend_06" type="hinge" axis="0 1 0" pos="-0.01909 0 0" range="-1.57 1.57" damping="0.012" stiffness="0.045" armature="0.0002" limited="true"/>
      <geom name="jar_03_bamboo_leaf_top_seg_06_geom" type="box" size="0.02138 0.04580 0.00150" material="compliant_bamboo_mat_top" mass="0.000909" friction="4 2 1" condim="6" contype="1" conaffinity="5"/>
      <body name="jar_03_bamboo_leaf_top_seg_07" pos="0.03818 0 0">
      <joint name="jar_03_bamboo_leaf_top_bend_07" type="hinge" axis="0 1 0" pos="-0.01909 0 0" range="-1.57 1.57" damping="0.012" stiffness="0.045" armature="0.0002" limited="true"/>
      <geom name="jar_03_bamboo_leaf_top_seg_07_geom" type="box" size="0.02138 0.04130 0.00150" material="compliant_bamboo_mat_top" mass="0.000909" friction="4 2 1" condim="6" contype="1" conaffinity="5"/>
      <body name="jar_03_bamboo_leaf_top_seg_08" pos="0.03818 0 0">
      <joint name="jar_03_bamboo_leaf_top_bend_08" type="hinge" axis="0 1 0" pos="-0.01909 0 0" range="-1.57 1.57" damping="0.012" stiffness="0.045" armature="0.0002" limited="true"/>
      <geom name="jar_03_bamboo_leaf_top_seg_08_geom" type="box" size="0.02138 0.03670 0.00150" material="compliant_bamboo_mat_top" mass="0.000909" friction="4 2 1" condim="6" contype="1" conaffinity="5"/>
      <body name="jar_03_bamboo_leaf_top_seg_09" pos="0.03818 0 0">
      <joint name="jar_03_bamboo_leaf_top_bend_09" type="hinge" axis="0 1 0" pos="-0.01909 0 0" range="-1.57 1.57" damping="0.012" stiffness="0.045" armature="0.0002" limited="true"/>
      <geom name="jar_03_bamboo_leaf_top_seg_09_geom" type="box" size="0.02138 0.02640 0.00150" material="compliant_bamboo_mat_top" mass="0.000909" friction="4 2 1" condim="6" contype="1" conaffinity="5"/>
      <body name="jar_03_bamboo_leaf_top_seg_10" pos="0.03818 0 0">
      <joint name="jar_03_bamboo_leaf_top_bend_10" type="hinge" axis="0 1 0" pos="-0.01909 0 0" range="-1.57 1.57" damping="0.012" stiffness="0.045" armature="0.0002" limited="true"/>
      <geom name="jar_03_bamboo_leaf_top_seg_10_geom" type="box" size="0.02138 0.01320 0.00150" material="compliant_bamboo_mat_top" mass="0.000909" friction="4 2 1" condim="6" contype="1" conaffinity="5"/>
      </body>
      </body>
      </body>
      </body>
      </body>
      <body name="jar_03_bamboo_leaf_top_seg_04" pos="-0.03818 0 0">
      <joint name="jar_03_bamboo_leaf_top_bend_05" type="hinge" axis="0 -1 0" pos="0.01909 0 0" range="-1.57 1.57" damping="0.012" stiffness="0.045" armature="0.0002" limited="true"/>
      <geom name="jar_03_bamboo_leaf_top_seg_04_geom" type="box" size="0.02138 0.04580 0.00150" material="compliant_bamboo_mat_top" mass="0.000909" friction="4 2 1" condim="6" contype="1" conaffinity="5"/>
      <body name="jar_03_bamboo_leaf_top_seg_03" pos="-0.03818 0 0">
      <joint name="jar_03_bamboo_leaf_top_bend_04" type="hinge" axis="0 -1 0" pos="0.01909 0 0" range="-1.57 1.57" damping="0.012" stiffness="0.045" armature="0.0002" limited="true"/>
      <geom name="jar_03_bamboo_leaf_top_seg_03_geom" type="box" size="0.02138 0.04130 0.00150" material="compliant_bamboo_mat_top" mass="0.000909" friction="4 2 1" condim="6" contype="1" conaffinity="5"/>
      <body name="jar_03_bamboo_leaf_top_seg_02" pos="-0.03818 0 0">
      <joint name="jar_03_bamboo_leaf_top_bend_03" type="hinge" axis="0 -1 0" pos="0.01909 0 0" range="-1.57 1.57" damping="0.012" stiffness="0.045" armature="0.0002" limited="true"/>
      <geom name="jar_03_bamboo_leaf_top_seg_02_geom" type="box" size="0.02138 0.03670 0.00150" material="compliant_bamboo_mat_top" mass="0.000909" friction="4 2 1" condim="6" contype="1" conaffinity="5"/>
      <body name="jar_03_bamboo_leaf_top_seg_01" pos="-0.03818 0 0">
      <joint name="jar_03_bamboo_leaf_top_bend_02" type="hinge" axis="0 -1 0" pos="0.01909 0 0" range="-1.57 1.57" damping="0.012" stiffness="0.045" armature="0.0002" limited="true"/>
      <geom name="jar_03_bamboo_leaf_top_seg_01_geom" type="box" size="0.02138 0.02640 0.00150" material="compliant_bamboo_mat_top" mass="0.000909" friction="4 2 1" condim="6" contype="1" conaffinity="5"/>
      <body name="jar_03_bamboo_leaf_top_seg_00" pos="-0.03818 0 0">
      <joint name="jar_03_bamboo_leaf_top_bend_01" type="hinge" axis="0 -1 0" pos="0.01909 0 0" range="-1.57 1.57" damping="0.012" stiffness="0.045" armature="0.0002" limited="true"/>
      <geom name="jar_03_bamboo_leaf_top_seg_00_geom" type="box" size="0.02138 0.01320 0.00150" material="compliant_bamboo_mat_top" mass="0.000909" friction="4 2 1" condim="6" contype="1" conaffinity="5"/>
      </body>
      </body>
      </body>
      </body>
      </body>
    </body>
    </body>

    <body name="station_wine_jar_02" pos="-2.40 0.05 0.125">
      <geom name="station_wine_jar_02_visual" type="mesh" mesh="wine_jar_mesh" material="jar_mat" contype="0" conaffinity="0"/>
      <geom name="station_wine_jar_02_belly_collision" type="cylinder" pos="0 0 0.205" size="0.16 0.205"
            material="jar_collision_mat" mass="8" friction="1 1 1" contype="2" conaffinity="1"/>
      <geom name="station_wine_jar_02_shoulder_collision" type="cylinder" pos="0 0 0.405" size="0.11 0.055"
            material="jar_collision_mat" mass="2" friction="1 1 1" contype="2" conaffinity="1"/>
      <geom name="station_wine_jar_02_neck_collision" type="cylinder" pos="0 0 0.4525" size="0.06 0.0075"
            material="jar_collision_mat" mass="1" friction="1 1 1" contype="2" conaffinity="1"/>
      <site name="jar_02_mouth_center" pos="0 0 0.46" type="sphere" size="0.010" rgba="1 0 0 0"/>
      <site name="jar_02_neck_tie_target" pos="0 0 0.452" type="sphere" size="0.010" rgba="0 0.7 1 0"/>
      <body name="jar_02_preloaded_lotus_leaf" pos="0 0 0.462" euler="0 0 0.42">
        <geom name="jar_02_preloaded_lotus_leaf_geom" type="mesh" mesh="cropped_lotus_leaf_tie_safe_mesh" material="lotus_mat" mass="0.02" friction="1 1 1"/>
      </body>
      <body name="jar_02_preloaded_white_paper" pos="0 0 0.467" euler="0 0 -0.18">
        <geom name="jar_02_preloaded_white_paper_geom" type="mesh" mesh="cropped_white_paper_mesh" material="paper_mat" mass="0.01" friction="1 1 1"/>
      </body>
      <body name="jar_02_preloaded_ceramic_disc" pos="0 0 0.476">
        <geom name="jar_02_preloaded_ceramic_disc_geom" type="cylinder" size="0.055 0.006" material="ceramic_mat" mass="0.20" friction="1 1 1"/>
      </body>
      <geom name="jar_02_mouth_support" type="cylinder" pos="0 0 0.488" size="0.130 0.002"
            rgba="0.2 0.6 0.2 0" contype="2" conaffinity="1" friction="8 3 2"/>
    </body>

    <body name="station_wine_jar_03" pos="-2.40 0.05 0.125">
      <geom name="station_wine_jar_03_visual" type="mesh" mesh="wine_jar_mesh" material="jar_mat" contype="0" conaffinity="0"/>
      <geom name="station_wine_jar_03_belly_collision" type="cylinder" pos="0 0 0.205" size="0.16 0.205"
            material="jar_collision_mat" mass="8" friction="1 1 1" contype="2" conaffinity="1"/>
      <geom name="station_wine_jar_03_shoulder_collision" type="cylinder" pos="0 0 0.405" size="0.11 0.055"
            material="jar_collision_mat" mass="2" friction="1 1 1" contype="2" conaffinity="1"/>
      <geom name="station_wine_jar_03_neck_collision" type="cylinder" pos="0 0 0.4525" size="0.06 0.0075"
            material="jar_collision_mat" mass="1" friction="1 1 1" contype="2" conaffinity="1"/>
      <site name="jar_03_mouth_center" pos="0 0 0.46" type="sphere" size="0.010" rgba="1 0 0 0"/>
      <site name="jar_03_neck_tie_target" pos="0 0 0.452" type="sphere" size="0.010" rgba="0 0.7 1 0"/>
      <body name="jar_03_preloaded_lotus_leaf" pos="0 0 0.462" euler="0 0 0.42">
        <geom name="jar_03_preloaded_lotus_leaf_geom" type="mesh" mesh="cropped_lotus_leaf_tie_safe_mesh" material="lotus_mat" mass="0.02" friction="1 1 1"/>
      </body>
      <body name="jar_03_preloaded_white_paper" pos="0 0 0.467" euler="0 0 -0.18">
        <geom name="jar_03_preloaded_white_paper_geom" type="mesh" mesh="cropped_white_paper_mesh" material="paper_mat" mass="0.01" friction="1 1 1"/>
      </body>
      <body name="jar_03_preloaded_ceramic_disc" pos="0 0 0.476">
        <geom name="jar_03_preloaded_ceramic_disc_geom" type="cylinder" size="0.055 0.006" material="ceramic_mat" mass="0.20" friction="1 1 1"/>
      </body>
      <geom name="jar_03_mouth_support" type="cylinder" pos="0 0 0.488" size="0.130 0.002"
            rgba="0.2 0.6 0.2 0" contype="2" conaffinity="1" friction="8 3 2"/>
    </body>
  </worldbody>
  <equality>
    <weld name="left_suction_weld_jar_02_leaf_top" body1="left_vacuum_end_effector" body2="jar_02_bamboo_leaf_top_seg_05" active="false" solref="0.004 1" solimp="0.95 0.99 0.001"/>
    <weld name="left_suction_weld_jar_02_leaf_bottom" body1="left_vacuum_end_effector" body2="jar_02_bamboo_leaf_bottom_seg_05" active="false" solref="0.004 1" solimp="0.95 0.99 0.001"/>
    <weld name="table_static_friction_weld_jar_02_leaf_top" body1="left_material_table" body2="jar_02_bamboo_leaf_top_seg_05" active="false" solref="0.030 1" solimp="0.70 0.95 0.010"/>
    <weld name="table_static_friction_weld_jar_02_leaf_bottom" body1="left_material_table" body2="jar_02_bamboo_leaf_bottom_seg_05" active="false" solref="0.030 1" solimp="0.70 0.95 0.010"/>
    <weld name="mouth_static_friction_weld_jar_02_leaf_top" body1="station_wine_jar_02" body2="jar_02_bamboo_leaf_top_seg_05" active="false" solref="0.030 1" solimp="0.70 0.95 0.010"/>
    <weld name="mouth_static_friction_weld_jar_02_leaf_bottom" body1="station_wine_jar_02" body2="jar_02_bamboo_leaf_bottom_seg_05" active="false" solref="0.030 1" solimp="0.70 0.95 0.010"/>
    <weld name="left_suction_weld_jar_03_leaf_top" body1="left_vacuum_end_effector" body2="jar_03_bamboo_leaf_top_seg_05" active="false" solref="0.004 1" solimp="0.95 0.99 0.001"/>
    <weld name="left_suction_weld_jar_03_leaf_bottom" body1="left_vacuum_end_effector" body2="jar_03_bamboo_leaf_bottom_seg_05" active="false" solref="0.004 1" solimp="0.95 0.99 0.001"/>
    <weld name="table_static_friction_weld_jar_03_leaf_top" body1="left_material_table" body2="jar_03_bamboo_leaf_top_seg_05" active="false" solref="0.030 1" solimp="0.70 0.95 0.010"/>
    <weld name="table_static_friction_weld_jar_03_leaf_bottom" body1="left_material_table" body2="jar_03_bamboo_leaf_bottom_seg_05" active="false" solref="0.030 1" solimp="0.70 0.95 0.010"/>
    <weld name="mouth_static_friction_weld_jar_03_leaf_top" body1="station_wine_jar_03" body2="jar_03_bamboo_leaf_top_seg_05" active="false" solref="0.030 1" solimp="0.70 0.95 0.010"/>
    <weld name="mouth_static_friction_weld_jar_03_leaf_bottom" body1="station_wine_jar_03" body2="jar_03_bamboo_leaf_bottom_seg_05" active="false" solref="0.030 1" solimp="0.70 0.95 0.010"/>
  </equality>
</mujoco>
